<?xml version="1.0" encoding="utf-8"?>
<robot name="SF_TRON1_ARM">
    <material name="black">
        <color rgba="0.0 0.0 0.0 1.0"/>
    </material>
    <material name="blue">
        <color rgba="0.0 0.0 0.8 1.0"/>
    </material>
    <material name="green">
        <color rgba="0.0 0.8 0.0 1.0"/>
    </material>
    <material name="grey">
        <color rgba="0.2 0.2 0.2 1.0"/>
    </material>
    <material name="silver">
        <color rgba="0.9137254901960784 0.9137254901960784 0.8470588235294118 1.0"/>
    </material>
    <material name="orange">
        <color rgba="1.0 0.4235294117647059 0.0392156862745098 1.0"/>
    </material>
    <material name="brown">
        <color rgba="0.8705882352941177 0.8117647058823529 0.7647058823529411 1.0"/>
    </material>
    <material name="red">
        <color rgba="0.8 0.0 0.0 1.0"/>
    </material>
    <material name="white">
        <color rgba="1.0 1.0 1.0 1.0"/>
    </material>
    <!-- ros_control plugin -->
    <gazebo>
        <plugin filename="libpointfoot_hw_sim.so" name="gazebo_ros_control">
            <robotNamespace>/</robotNamespace>
            <robotParam>robot_description</robotParam>
            <robotSimType>pointfoot_gazebo/PointFootHWSim</robotSimType>
        </plugin>
    </gazebo>
    <gazebo>
        <plugin filename="libgazebo_ros_p3d.so" name="p3d_base_controller">
            <alwaysOn>true</alwaysOn>
            <updateRate>1000.0</updateRate>
            <bodyName>base_Link</bodyName>
            <topicName>ground_truth/state</topicName>
            <gaussianNoise>0</gaussianNoise>
            <frameName>world</frameName>
            <xyzOffsets>0 0 0</xyzOffsets>
            <rpyOffsets>0 0 0</rpyOffsets>
        </plugin>
    </gazebo>
    <!-- <link name="world" /> -->
    <!-- world is fixed to the base link -->
    <!-- <joint name="fixed" type="fixed">
        <origin xyz="0 0 0.8" rpy="0 0 0" />
        <parent link="world" />
        <child link="base_Link" />
    </joint> -->
    <link
            name="base_Link">
        <inertial>
            <origin rpy="0 0 0" xyz="45.76E-03 0.14E-03 -163.98E-03"/>
            <mass value="9.585"/>
            <inertia ixx="140110.479E-06" ixy="534.939E-06" ixz="28184.116E-06"
                     iyy="110641.449E-06" iyz="-27.278E-06" izz="98944.542E-06"/>
        </inertial>
        <visual>
            <origin
                    xyz="0 0 0"
                    rpy="0 0 0"/>
            <geometry>
                <mesh
                        filename="package://robot_description/pointfoot/SF_TRON1A/meshes/base_Link.STL"/>
            </geometry>
            <material
                    name="">
                <color
                        rgba="0.79216 0.81961 0.93333 1"/>
            </material>
        </visual>
        <collision>
            <origin xyz="0.03 0 -0.072" rpy="0 0 0"/>
            <geometry>
                <box size="0.27 0.26 0.19"/>
            </geometry>
        </collision>
    </link>

     <joint name="limx_imu_joint" type="fixed">
        <origin rpy="0. 0. 0." xyz="0. 0. 0."/>
        <parent link="base_Link"/>
        <child link="limx_imu"/>
    </joint>
    <!-- Imu link -->
    <link name="limx_imu">
        <inertial>
            <mass value="0.01"/>
            <origin rpy="0 0 0" xyz="0 0 0"/>
            <inertia ixx="0.000001" ixy="0" ixz="0" iyy="0.000001" iyz="0" izz="0.000001"/>
        </inertial>
        <visual>
            <origin rpy="0 0 0" xyz="0 0 0"/>
            <geometry>
                <box size="0.015 0.015 0.004"/>
            </geometry>
        </visual>
        <material name="orange">
            <color rgba="255 108 10 255"/>
        </material>
    </link>
    <gazebo reference="limx_imu">
        <material>Gazebo/Orange</material>
    </gazebo>
    <gazebo reference="limx_imu_joint">
        <disableFixedJointLumping>true</disableFixedJointLumping>
    </gazebo>
    
    <link
            name="abad_L_Link">
        <inertial>
            <origin rpy="0 0 0" xyz="-69.77E-03 44.79E-03 0.57E-03"/>
            <mass value="1.469"/>
            <inertia ixx="1555.384E-06" ixy="397.78E-06" ixz="-13.10E-06"
                     iyy="2359.25E-06" iyz="-0.98E-06" izz="2080.92E-06"/>
        </inertial>
        <visual>
            <origin
                    xyz="0 0 0"
                    rpy="0 0 0"/>
            <geometry>
                <mesh
                        filename="package://robot_description/pointfoot/SF_TRON1A/meshes/abad_L_Link.STL"/>
            </geometry>
            <material
                    name="">
                <color
                        rgba="0.79216 0.81961 0.93333 1"/>
            </material>
        </visual>
        <collision>
            <origin xyz="0.03 0 0" rpy="1.57 0 1.57"/>
            <geometry>
                <cylinder length="0.05" radius="0.05"/>
            </geometry>
        </collision>
    </link>
    <joint
            name="abad_L_Joint"
            type="revolute">
        <origin
                xyz="55.56E-03 105E-03 -260.2E-03"
                rpy="0 0 0"/>
        <parent
                link="base_Link"/>
        <child
                link="abad_L_Link"/>
        <axis
                xyz="1 0 0"/>
        <limit effort="80.0" lower="-0.38397" upper="1.39626" velocity="15.0"/>
    </joint>
    <link
            name="hip_L_Link">
        <inertial>
            <origin rpy="0 0 0" xyz="-28.69E-03 -47.7E-03 -39.92E-03"/>
            <mass value="2.30"/>
            <inertia ixx="16937.28E-06" ixy="1647.03E-06" ixz="-9232.53E-06"
                     iyy="22853.28E-06" iyz="2202.40E-06" izz="9334.19E-06"/>
        </inertial>
        <visual>
            <origin
                    xyz="0 0 0"
                    rpy="0 0 0"/>
            <geometry>
                <mesh
                        filename="package://robot_description/pointfoot/SF_TRON1A/meshes/hip_L_Link.STL"/>
            </geometry>
            <material
                    name="">
                <color
                        rgba="1 1 1 1"/>
            </material>
        </visual>
        <collision>
            <origin xyz="-0.10 -0.03 -0.14" rpy="0 0.53 0"/>
            <geometry>
                <cylinder length="0.15" radius="0.035"/>
            </geometry>
        </collision>
    </link>
    <joint
            name="hip_L_Joint"
            type="revolute">
        <origin
                xyz="-0.077 0.02050 0"
                rpy="0 0 0"/>
        <parent
                link="abad_L_Link"/>
        <child
                link="hip_L_Link"/>
        <axis
                xyz="0 1 0"/>
        <limit effort="80.0" lower="-1.012291" upper="1.396263" velocity="15.0"/>
    </joint>
    <link
            name="knee_L_Link">
        <inertial>
            <origin rpy="0 0 0" xyz="114.52E-03 1.3E-03 -193.67E-03"/>
            <mass value="1.22"/>
            <inertia ixx="10938.43E-06" ixy="-7.87E-06" ixz="5986.5E-06"
                     iyy="14358.12E-06" iyz="10.11E-06" izz="4087.65E-06"/>
        </inertial>
        <visual>
            <origin
                    xyz="0 0 0"
                    rpy="0 0 0"/>
            <geometry>
                <mesh
                        filename="package://robot_description/pointfoot/SF_TRON1A/meshes/knee_L_Link.STL"/>
            </geometry>
            <material
                    name="">
                <color
                        rgba="0.79216 0.81961 0.93333 1"/>
            </material>
        </visual>
        <collision>
            <origin xyz="0.078 0 -0.12" rpy="0 -0.55 0"/>
            <geometry>
                <cylinder length="0.26" radius="0.02"/>
            </geometry>
        </collision>
    </link>
    <joint
            name="knee_L_Joint"
            type="revolute">
        <origin
                xyz="-0.1500 -0.02050 -0.25981"
                rpy="0 0 0"/>
        <parent
                link="hip_L_Link"/>
        <child
                link="knee_L_Link"/>
        <axis
                xyz="0 -1 0"/>
        <limit effort="80" lower="-0.872665" upper="1.361357" velocity="15"/>
    </joint>
    <link
            name="ankle_L_Link">
        <inertial>
            <origin rpy="0 0 0" xyz="10.74E-03 -0.61E-03 -33.14E-03"/>
            <mass value="0.62" />
            <inertia ixx="525.46E-06" ixy="-3.51E-06" ixz="-51.36E-06"
                     iyy="1812.05E-06" iyz="6.54E-06" izz="1973.81E-06" />
        </inertial>
        <visual>
            <origin
                    xyz="0 0 0"
                    rpy="0 0 0"/>
            <geometry>
                <mesh
                        filename="package://robot_description/pointfoot/SF_TRON1A/meshes/ankle_L_Link.STL"/>
            </geometry>
            <material
                    name="">
                <color
                        rgba="0.26667 0.26667 0.26667 1"/>
            </material>
        </visual>
        <collision>
            <origin
                    xyz="0 0 0"
                    rpy="0 0 0"/>
            <geometry>
                <mesh
                        filename="package://robot_description/pointfoot/SF_TRON1A/meshes/ankle_L_Link.STL"/>
            </geometry>
            <material
                    name="">
                <color
                        rgba="0.26667 0.26667 0.26667 1"/>
            </material>
        </collision>
    </link>
    <joint
            name="ankle_L_Joint"
            type="revolute">
        <origin
                xyz="0.150 0 -0.25981"
                rpy="0 0 0"/>
        <parent
                link="knee_L_Link"/>
        <child
                link="ankle_L_Link"/>
        <axis
                xyz="0 -1 0"/>

        <limit effort="20" lower="-1.15191730631626" upper="1.5707963267949" velocity="15"/>
        <dynamics friction="0.01"/>
    </joint>
    <gazebo reference="hip_L_Link">
        <mu1>0.2</mu1>
        <mu2>0.2</mu2>
        <material>Gazebo/DarkGrey</material>
    </gazebo>
    <gazebo reference="knee_L_Link">
        <mu1>0.2</mu1>
        <mu2>0.2</mu2>
        <self_collide>0</self_collide>
        <material>Gazebo/DarkGrey</material>
        <kp value="1000000.0"/>
        <kd value="100.0"/>
    </gazebo>
    <gazebo reference="ankle_L_Link">
        <mu1>4.0</mu1>
        <mu2>4.0</mu2>
        <self_collide>1</self_collide>
        <material>Gazebo/DarkGrey</material>
        <kp value="600000.0"/>
        <kd value="100.0"/>
    </gazebo>

    <transmission name="abad_L_Joint_tran">
        <type>transmission_interface/SimpleTransmission</type>
        <joint name="abad_L_Joint">
            <hardwareInterface>hardware_interface/EffortJointInterface</hardwareInterface>
        </joint>
        <actuator name="abad_L_Joint_motor">
            <hardwareInterface>hardware_interface/EffortJointInterface</hardwareInterface>
            <mechanicalReduction>1</mechanicalReduction>
        </actuator>
    </transmission>
    <transmission name="hip_L_Joint_tran">
        <type>transmission_interface/SimpleTransmission</type>
        <joint name="hip_L_Joint">
            <hardwareInterface>hardware_interface/EffortJointInterface</hardwareInterface>
        </joint>
        <actuator name="hip_L_Joint_motor">
            <hardwareInterface>hardware_interface/EffortJointInterface</hardwareInterface>
            <mechanicalReduction>1</mechanicalReduction>
        </actuator>
    </transmission>
    <transmission name="knee_L_Joint_tran">
        <type>transmission_interface/SimpleTransmission</type>
        <joint name="knee_L_Joint">
            <hardwareInterface>hardware_interface/EffortJointInterface</hardwareInterface>
        </joint>
        <actuator name="knee_L_Joint_motor">
            <hardwareInterface>hardware_interface/EffortJointInterface</hardwareInterface>
            <mechanicalReduction>1</mechanicalReduction>
        </actuator>
    </transmission>

    <transmission name="ankle_L_Joint_tran">
        <type>transmission_interface/SimpleTransmission</type>
        <joint name="ankle_L_Joint">
            <hardwareInterface>hardware_interface/EffortJointInterface</hardwareInterface>
        </joint>
        <actuator name="ankle_L_Joint_motor">
            <hardwareInterface>hardware_interface/EffortJointInterface</hardwareInterface>
            <mechanicalReduction>1</mechanicalReduction>
        </actuator>
    </transmission>

    <link
            name="abad_R_Link">
        <inertial>
            <origin rpy="0 0 0" xyz="-69.77E-03 -44.79E-03 0.57E-03"/>
            <mass value="1.469"/>
            <inertia ixx="1555.384E-06" ixy="-397.78E-06" ixz="-13.10E-06"
                     iyy="2359.25E-06" iyz="0.98E-06" izz="2080.92E-06"/>
        </inertial>
        <visual>
            <origin
                    xyz="0 0 0"
                    rpy="0 0 0"/>
            <geometry>
                <mesh
                        filename="package://robot_description/pointfoot/SF_TRON1A/meshes/abad_R_Link.STL"/>
            </geometry>
            <material
                    name="">
                <color
                        rgba="0.79216 0.81961 0.93333 1"/>
            </material>
        </visual>
        <collision>
            <origin xyz="0.03 0 0" rpy="1.57 0 1.57"/>
            <geometry>
                <cylinder length="0.05" radius="0.05"/>
            </geometry>
        </collision>
    </link>
    <joint
            name="abad_R_Joint"
            type="revolute">
        <origin
                xyz="55.56E-03 -105E-03 -260.2E-03"
                rpy="0 0 0"/>
        <parent
                link="base_Link"/>
        <child
                link="abad_R_Link"/>
        <axis
                xyz="1 0 0"/>
        <limit effort="80.0" lower="-1.39626" upper="0.38397" velocity="15.0"/>
    </joint>
    <link
            name="hip_R_Link">
        <inertial>
            <origin rpy="0 0 0" xyz="-28.69E-03 47.7E-03 -39.92E-03"/>
            <mass value="2.30"/>
            <inertia ixx="16937.28E-06" ixy="-1647.03E-06" ixz="-9232.53E-06"
                     iyy="22853.28E-06" iyz="-2202.40E-06" izz="9334.19E-06"/>
        </inertial>
        <visual>
            <origin
                    xyz="0 0 0"
                    rpy="0 0 0"/>
            <geometry>
                <mesh
                        filename="package://robot_description/pointfoot/SF_TRON1A/meshes/hip_R_Link.STL"/>
            </geometry>
            <material
                    name="">
                <color
                        rgba="1 1 1 1"/>
            </material>
        </visual>
        <collision>
            <origin xyz="-0.10 0.03 -0.14" rpy="0 0.53 0"/>
            <geometry>
                <cylinder length="0.15" radius="0.035"/>
            </geometry>
        </collision>
    </link>
    <joint
            name="hip_R_Joint"
            type="revolute">
        <origin
                xyz="-0.077 -0.02050 0"
                rpy="0 0 0"/>
        <parent
                link="abad_R_Link"/>
        <child
                link="hip_R_Link"/>
        <axis
                xyz="0 -1 0"/>
        <limit effort="80.0" lower="-1.396263" upper="1.012291" velocity="15.0"/>
    </joint>
    <link
            name="knee_R_Link">
        <inertial>
            <origin rpy="0 0 0" xyz="114.52E-03 -1.3E-03 -193.67E-03"/>
            <mass value="1.22"/>
            <inertia ixx="10938.43E-06" ixy="7.87E-06" ixz="5986.5E-06"
                     iyy="14358.12E-06" iyz="-10.11E-06" izz="4087.65E-06"/>
        </inertial>
        <visual>
            <origin
                    xyz="0 0 0"
                    rpy="0 0 0"/>
            <geometry>
                <mesh
                        filename="package://robot_description/pointfoot/SF_TRON1A/meshes/knee_R_Link.STL"/>
            </geometry>
            <material
                    name="">
                <color
                        rgba="0.79216 0.81961 0.93333 1"/>
            </material>
        </visual>
        <collision>
            <origin xyz="0.078 0 -0.12" rpy="0 -0.55 0"/>
            <geometry>
                <cylinder length="0.26" radius="0.02"/>
            </geometry>
        </collision>
    </link>
    <joint
            name="knee_R_Joint"
            type="revolute">
        <origin
                xyz="-0.1500 0.02050 -0.25981"
                rpy="0 0 0"/>
        <parent
                link="hip_R_Link"/>
        <child
                link="knee_R_Link"/>
        <axis
                xyz="0 1 0"/>
        <limit effort="80" lower="-1.361357" upper="0.872665" velocity="15"/>
    </joint>
    <link
            name="ankle_R_Link">
        <inertial>
            <origin rpy="0 0 0" xyz="10.74E-03 0.61E-03 -33.14E-03"/>
            <mass value="0.62" />
            <inertia ixx="525.46E-06" ixy="3.51E-06" ixz="-51.36E-06"
                iyy="1812.05E-06" iyz="-6.54E-06" izz="1973.81E-06" />
        </inertial>
        <visual>
            <origin
                    xyz="0 0 0"
                    rpy="0 0 0"/>
            <geometry>
                <mesh
                        filename="package://robot_description/pointfoot/SF_TRON1A/meshes/ankle_R_Link.STL"/>
            </geometry>
            <material
                    name="">
                <color
                        rgba="0.26667 0.26667 0.26667 1"/>
            </material>
        </visual>
        <collision>
            <origin
                    xyz="0 0 0"
                    rpy="0 0 0"/>
            <geometry>
                <mesh
                        filename="package://robot_description/pointfoot/SF_TRON1A/meshes/ankle_R_Link.STL"/>
            </geometry>
            <material
                    name="">
                <color
                        rgba="0.26667 0.26667 0.26667 1"/>
            </material>
        </collision>
    </link>
    <joint
            name="ankle_R_Joint"
            type="revolute">
        <origin
                xyz="0.150 0 -0.25981"
                rpy="0 0 0"/>
        <parent
                link="knee_R_Link"/>
        <child
                link="ankle_R_Link"/>
        <axis
                xyz="0 -1 0"/>

        <limit effort="20" lower="-1.15191730631626" upper="1.5707963267949" velocity="15"/>
        <dynamics friction="0.01"/>
    </joint>
    <gazebo reference="hip_R_Link">
        <mu1>0.2</mu1>
        <mu2>0.2</mu2>
        <material>Gazebo/DarkGrey</material>
    </gazebo>
    <gazebo reference="knee_R_Link">
        <mu1>0.2</mu1>
        <mu2>0.2</mu2>
        <self_collide>0</self_collide>
        <material>Gazebo/DarkGrey</material>
        <kp value="1000000.0"/>
        <kd value="100.0"/>
    </gazebo>
    <gazebo reference="ankle_R_Link">
        <mu1>4.0</mu1>
        <mu2>4.0</mu2>
        <self_collide>1</self_collide>
        <material>Gazebo/DarkGrey</material>
        <kp value="600000.0"/>
        <kd value="100.0"/>
    </gazebo>

    <transmission name="abad_R_Joint_tran">
        <type>transmission_interface/SimpleTransmission</type>
        <joint name="abad_R_Joint">
            <hardwareInterface>hardware_interface/EffortJointInterface</hardwareInterface>
        </joint>
        <actuator name="abad_R_Joint_motor">
            <hardwareInterface>hardware_interface/EffortJointInterface</hardwareInterface>
            <mechanicalReduction>1</mechanicalReduction>
        </actuator>
    </transmission>
    <transmission name="hip_R_Joint_tran">
        <type>transmission_interface/SimpleTransmission</type>
        <joint name="hip_R_Joint">
            <hardwareInterface>hardware_interface/EffortJointInterface</hardwareInterface>
        </joint>
        <actuator name="hip_R_Joint_motor">
            <hardwareInterface>hardware_interface/EffortJointInterface</hardwareInterface>
            <mechanicalReduction>1</mechanicalReduction>
        </actuator>
    </transmission>
    <transmission name="knee_R_Joint_tran">
        <type>transmission_interface/SimpleTransmission</type>
        <joint name="knee_R_Joint">
            <hardwareInterface>hardware_interface/EffortJointInterface</hardwareInterface>
        </joint>
        <actuator name="knee_R_Joint_motor">
            <hardwareInterface>hardware_interface/EffortJointInterface</hardwareInterface>
            <mechanicalReduction>1</mechanicalReduction>
        </actuator>
    </transmission>
    <transmission name="ankle_R_Joint_tran">
        <type>transmission_interface/SimpleTransmission</type>
        <joint name="ankle_R_Joint">
            <hardwareInterface>hardware_interface/EffortJointInterface</hardwareInterface>
        </joint>
        <actuator name="ankle_R_Joint_motor">
            <hardwareInterface>hardware_interface/EffortJointInterface</hardwareInterface>
            <mechanicalReduction>1</mechanicalReduction>
        </actuator>
    </transmission>

    <!-- ****************************************** robot arm ******************************************************** -->
    
    <joint name="arxr5_arm_adapter_joint" type="fixed">
        <origin rpy="0. 0. 0.0" xyz="0.00166 0 0.0195"/>
        <parent link="base_Link"/>
        <child link="arxr5_arm_adapter"/>
    </joint>
    
    <link name="arxr5_arm_adapter">
        <inertial>
            <origin xyz="0 0 0.0" rpy="0 0 0" />
            <mass value="0.17" />
            <inertia ixx="0.00044301" ixy="0" ixz="0" iyy="0.00035087" iyz="0" izz="0.00079287" />
        </inertial>
        <visual>
            <origin xyz="0 0 0" rpy="0 0 0" />
            <geometry>
                <box size="0.15 0.15 0.006"/>
            </geometry>
        </visual>
    </link>
    
    <joint name="arm_base_joint" type="fixed">
        <origin rpy="0 0 0" xyz="0.0245 0. 0.003"/>
        <parent link="arxr5_arm_adapter"/>
        <child link="base_link_arm"/>
    </joint>

    <link
    name="base_link_arm">
    <inertial>
      <origin
        xyz="-0.00013359 6.672E-05 0.031672"
        rpy="0 0 0" />
      <mass
        value="0.42272" />
      <inertia
        ixx="0.00019"
        ixy="0.00000"
        ixz="0.00000"
        iyy="0.00019"
        iyz="0.00000"
        izz="0.00020" />
    </inertial>
    <visual>
      <origin
        xyz="0 0 0"
        rpy="0 0 0" />
      <geometry>
        <mesh
          filename="/home/phi/CLX/projects/loco_manipulation/IsaacLab_RFM/source/ext_loco/ext_loco/assets/WF_TRON1A_ARXR5ARM/urdf/wf_ton1a_armr5_arm_urdf/meshes/base_link_arm.STL" />
      </geometry>
      <material
        name="">
        <color
          rgba="0.89804 0.91765 0.92941 1" />
      </material>
    </visual>
    <!-- <collision>
      <origin
        xyz="0 0 0"
        rpy="0 0 0" />
      <geometry>
        <mesh
          filename="/home/phi/CLX/projects/loco_manipulation/IsaacLab_RFM/source/ext_loco/ext_loco/assets/WF_TRON1A_ARXR5ARM/urdf/wf_ton1a_armr5_arm_urdf/meshes/base_link_arm.STL" />
      </geometry>
    </collision> -->
  </link>

  <link
    name="link1">
    <inertial>
      <origin
        xyz="0.0050395 -0.0077407 0.020897"
        rpy="0 0 0" />
      <mass
        value="0.096804" />
      <inertia
        ixx="0.00011"
        ixy="-0.00001"
        ixz="0.00001"
        iyy="0.00005"
        iyz="-0.00001"
        izz="0.00010" />
    </inertial>
    <visual>
      <origin
        xyz="0 0 0"
        rpy="0 0 0" />
      <geometry>
        <mesh
          filename="/home/phi/CLX/projects/loco_manipulation/IsaacLab_RFM/source/ext_loco/ext_loco/assets/WF_TRON1A_ARXR5ARM/urdf/wf_ton1a_armr5_arm_urdf/meshes/link1.STL" />
      </geometry>
      <material
        name="">
        <color
          rgba="0.56471 0.56471 0.56471 1" />
      </material>
    </visual>
    <collision>
      <origin
        xyz="0 0 0"
        rpy="0 0 0" />
      <geometry>
        <mesh
          filename="/home/phi/CLX/projects/loco_manipulation/IsaacLab_RFM/source/ext_loco/ext_loco/assets/WF_TRON1A_ARXR5ARM/urdf/wf_ton1a_armr5_arm_urdf/meshes/link1.STL" />
      </geometry>
    </collision>
  </link>
  <joint
    name="J1"
    type="revolute">
    <origin
      xyz="0 0 0.0565"
      rpy="0 0 0" />
    <parent
      link="base_link_arm" />
    <child
      link="link1" />
    <axis
      xyz="0 0 1" />
    <!-- <limit lower="-10" upper="10" effort="100" velocity="1000" /> -->
    <limit lower="-3.14" upper="2.618" effort="30" velocity="5" />
  </joint>

  <link
    name="link2">
    <inertial>
      <origin
        xyz="-0.12992 -0.0011822 -2.6366E-05"
        rpy="0 0 0" />
      <mass
        value="1.1988" />
      <inertia
        ixx="0.00065"
        ixy="0.00008"
        ixz="0.00000"
        iyy="0.01647"
        iyz="0.00000"
        izz="0.01646" />
    </inertial>
    <visual>
      <origin
        xyz="0 0 0"
        rpy="0 0 0" />
      <geometry>
        <mesh
          filename="/home/phi/CLX/projects/loco_manipulation/IsaacLab_RFM/source/ext_loco/ext_loco/assets/WF_TRON1A_ARXR5ARM/urdf/wf_ton1a_armr5_arm_urdf/meshes/link2.STL" />
      </geometry>
      <material
        name="">
        <color
          rgba="0.79216 0.81961 0.93333 1" />
      </material>
    </visual>
    <collision>
      <origin
        xyz="0 0 0"
        rpy="0 0 0" />
      <geometry>
        <mesh
          filename="/home/phi/CLX/projects/loco_manipulation/IsaacLab_RFM/source/ext_loco/ext_loco/assets/WF_TRON1A_ARXR5ARM/urdf/wf_ton1a_armr5_arm_urdf/meshes/link2.STL" />
      </geometry>
    </collision>
  </link>

  <joint
    name="J2"
    type="revolute">
    <origin
      xyz="0.02 0 0.047"
      rpy="0 0 0" />
    <parent
      link="link1" />
    <child
      link="link2" />
    <axis
      xyz="0 1 0" />
    <!-- <limit
      lower="-10"
      upper="10"
      effort="100"
      velocity="1000" /> -->
    <limit lower="-0.05" upper="3.50" effort="40" velocity="5" />
  </joint>

  <link
    name="link3">
    <inertial>
      <origin
        xyz="0.16181 0.0011723 -0.05455"
        rpy="0 0 0" />
      <mass
        value="0.84082" />
      <inertia
        ixx="0.00082"
        ixy="0.00008"
        ixz="-0.00074"
        iyy="0.00849"
        iyz="0.00001"
        izz="0.00834" />
    </inertial>
    <visual>
      <origin
        xyz="0 0 0"
        rpy="0 0 0" />
      <geometry>
        <mesh
          filename="/home/phi/CLX/projects/loco_manipulation/IsaacLab_RFM/source/ext_loco/ext_loco/assets/WF_TRON1A_ARXR5ARM/urdf/wf_ton1a_armr5_arm_urdf/meshes/link3.STL" />
      </geometry>
      <material
        name="">
        <color
          rgba="0.89804 0.91765 0.92941 1" />
      </material>
    </visual>
    <collision>
      <origin
        xyz="0 0 0"
        rpy="0 0 0" />
      <geometry>
        <mesh
          filename="/home/phi/CLX/projects/loco_manipulation/IsaacLab_RFM/source/ext_loco/ext_loco/assets/WF_TRON1A_ARXR5ARM/urdf/wf_ton1a_armr5_arm_urdf/meshes/link3.STL" />
      </geometry>
    </collision>
  </link>

  <joint
    name="J3"
    type="revolute">
    <origin
      xyz="-0.264 0 0"
      rpy="-3.1416 0 0" />
    <parent
      link="link2" />
    <child
      link="link3" />
    <axis
      xyz="0 1 0" />
    <!-- <limit
      lower="-10"
      upper="10"
      effort="100"
      velocity="1000" /> -->
    <limit lower="-0.1" upper="3.2" effort="30" velocity="5.5" /> 
  </joint>

  <link
    name="link4">
    <inertial>
      <origin
        xyz="0.041751 0.0054236 -0.03337"
        rpy="0 0 0" />
      <mass
        value="0.12432" />
      <inertia
        ixx="0.00022"
        ixy="-0.00002"
        ixz="-0.00009"
        iyy="0.00025"
        iyz="0.00002"
        izz="0.00017" />
    </inertial>
    <visual>
      <origin
        xyz="0 0 0"
        rpy="0 0 0" />
      <geometry>
        <mesh
          filename="/home/phi/CLX/projects/loco_manipulation/IsaacLab_RFM/source/ext_loco/ext_loco/assets/WF_TRON1A_ARXR5ARM/urdf/wf_ton1a_armr5_arm_urdf/meshes/link4.STL" />
      </geometry>
      <material
        name="">
        <color
          rgba="0.79216 0.81961 0.93333 1" />
      </material>
    </visual>
    <collision>
      <origin
        xyz="0 0 0"
        rpy="0 0 0" />
      <geometry>
        <mesh
          filename="/home/phi/CLX/projects/loco_manipulation/IsaacLab_RFM/source/ext_loco/ext_loco/assets/WF_TRON1A_ARXR5ARM/urdf/wf_ton1a_armr5_arm_urdf/meshes/link4.STL" />
      </geometry>
    </collision>
  </link>
  <joint
    name="J4"
    type="revolute">
    <origin
      xyz="0.245 -5E-05 -0.06"
      rpy="0 0 0" />
    <parent
      link="link3" />
    <child
      link="link4" />
    <axis
      xyz="0 1 0" />
    <!-- <limit
      lower="-10"
      upper="10"
      effort="100"
      velocity="1000" /> -->
    <limit lower="-1.6" upper="1.55" effort="15" velocity="5.5" />

  </joint>
  <link
    name="link5">
    <inertial>
      <origin
        xyz="-8.3435E-05 -1.5428E-05 0.052216"
        rpy="0 0 0" />
      <mass
        value="0.63601" />
      <inertia
        ixx="0.00084"
        ixy="0.00000"
        ixz="0.00007"
        iyy="0.00082"
        iyz="0.00000"
        izz="0.00026" />
    </inertial>
    <visual>
      <origin
        xyz="0 0 0"
        rpy="0 0 0" />
      <geometry>
        <mesh
          filename="/home/phi/CLX/projects/loco_manipulation/IsaacLab_RFM/source/ext_loco/ext_loco/assets/WF_TRON1A_ARXR5ARM/urdf/wf_ton1a_armr5_arm_urdf/meshes/link5.STL" />
      </geometry>
      <material
        name="">
        <color
          rgba="0.69804 0.69804 0.69804 1" />
      </material>
    </visual>
    <collision>
      <origin
        xyz="0 0 0"
        rpy="0 0 0" />
      <geometry>
        <mesh
          filename="/home/phi/CLX/projects/loco_manipulation/IsaacLab_RFM/source/ext_loco/ext_loco/assets/WF_TRON1A_ARXR5ARM/urdf/wf_ton1a_armr5_arm_urdf/meshes/link5.STL" />
      </geometry>
    </collision>
  </link>

  <joint
    name="J5"
    type="revolute">
    <origin
      xyz="0.073914 5E-05 -0.083391"
      rpy="0 0 0" />
    <parent
      link="link4" />
    <child
      link="link5" />
    <axis
      xyz="0 0 1" />
    <!-- <limit
      lower="-10"
      upper="10"
      effort="100"
      velocity="1000" /> -->
    <limit lower="-1.57" upper="1.57" effort="10" velocity="5" />

  </joint>
  <link
    name="link6">
    <inertial>
      <origin
        xyz="0.041697 2.4368E-05 0.00014464"
        rpy="0 0 0" />
      <mass
        value="0.44089" />
      <inertia
        ixx="0.00038"
        ixy="0.00000"
        ixz="0.00000"
        iyy="0.00028"
        iyz="0.00000"
        izz="0.00050" />
    </inertial>
    <visual>
      <origin
        xyz="0 0 0"
        rpy="0 0 0" />
      <geometry>
        <mesh
          filename="/home/phi/CLX/projects/loco_manipulation/IsaacLab_RFM/source/ext_loco/ext_loco/assets/WF_TRON1A_ARXR5ARM/urdf/wf_ton1a_armr5_arm_urdf/meshes/link6.STL" />
      </geometry>
      <material
        name="">
        <color
          rgba="0.89804 0.91765 0.92941 1" />
      </material>
    </visual>
    <collision>
      <origin
        xyz="0 0 0"
        rpy="0 0 0" />
      <geometry>
        <mesh
          filename="/home/phi/CLX/projects/loco_manipulation/IsaacLab_RFM/source/ext_loco/ext_loco/assets/WF_TRON1A_ARXR5ARM/urdf/wf_ton1a_armr5_arm_urdf/meshes/link6.STL" />
      </geometry>
    </collision>
  </link>

  <joint
    name="J6"
    type="revolute">
    <origin
      xyz="0.025286 0 0.083391"
      rpy="3.1416 0 0" />
    <parent
      link="link5" />
    <child
      link="link6" />
    <axis
      xyz="1 0 0" />
    <!-- <limit
      lower="-10"
      upper="10"
      effort="100"
      velocity="1000" /> -->
    <limit lower="-2" upper="2" effort="10" velocity="5" />

  </joint>
  <link
    name="link7">
    <inertial>
      <origin
        xyz="-0.00035522 -0.007827 -0.0029883"
        rpy="0 0 0" />
      <mass
        value="0.064798" />
      <inertia
        ixx="0.00002"
        ixy="0.00000"
        ixz="0.00000"
        iyy="0.00003"
        iyz="0.00000"
        izz="0.00003" />
    </inertial>
    <visual>
      <origin
        xyz="0 0 0"
        rpy="0 0 0" />
      <geometry>
        <mesh
          filename="/home/phi/CLX/projects/loco_manipulation/IsaacLab_RFM/source/ext_loco/ext_loco/assets/WF_TRON1A_ARXR5ARM/urdf/wf_ton1a_armr5_arm_urdf/meshes/link7.STL" />
      </geometry>
      <material
        name="">
        <color
          rgba="1 1 1 1" />
      </material>
    </visual>
    <collision>
      <origin
        xyz="0 0 0"
        rpy="0 0 0" />
      <geometry>
        <mesh
          filename="/home/phi/CLX/projects/loco_manipulation/IsaacLab_RFM/source/ext_loco/ext_loco/assets/WF_TRON1A_ARXR5ARM/urdf/wf_ton1a_armr5_arm_urdf/meshes/link7.STL" />
      </geometry>
    </collision>
  </link>
  <joint
    name="joint7"
    type="fixed">
    <origin
      xyz="0.08657 0.024896 -0.0002436"
      rpy="0 0 0" />
    <parent
      link="link6" />
    <child
      link="link7" />
    <axis
      xyz="0 1 0" />
    <limit
      lower="0"
      upper="0.044"
      effort="100"
      velocity="1000" />
  </joint>
  <link
    name="link8">
    <inertial>
      <origin
        xyz="-0.000355223470270755 0.00782768751820277 0.00242005642879778"
        rpy="0 0 0" />
      <mass
        value="0.0647981725781684" />
      <inertia
        ixx="0.00002"
        ixy="0.00000"
        ixz="0.00000"
        iyy="0.00003"
        iyz="0.00000"
        izz="0.00003" />
    </inertial>
    <visual>
      <origin
        xyz="0 0 0"
        rpy="0 0 0" />
      <geometry>
        <mesh
          filename="/home/phi/CLX/projects/loco_manipulation/IsaacLab_RFM/source/ext_loco/ext_loco/assets/WF_TRON1A_ARXR5ARM/urdf/wf_ton1a_armr5_arm_urdf/meshes/link8.STL" />
      </geometry>
      <material
        name="">
        <color
          rgba="1 1 1 1" />
      </material>
    </visual>
    <collision>
      <origin
        xyz="0 0 0"
        rpy="0 0 0" />
      <geometry>
        <mesh
          filename="/home/phi/CLX/projects/loco_manipulation/IsaacLab_RFM/source/ext_loco/ext_loco/assets/WF_TRON1A_ARXR5ARM/urdf/wf_ton1a_armr5_arm_urdf/meshes/link8.STL" />
      </geometry>
    </collision>
  </link>
  <joint
    name="joint8"
    type="fixed">
    <origin
      xyz="0.08657 -0.0249 -0.00024366"
      rpy="0 0 0" />
    <parent
      link="link6" />
    <child
      link="link8" />
    <axis
      xyz="0 -1 0" />
    <limit
      lower="0"
      upper="0.044"
      effort="100"
      velocity="1000" />
  </joint>

    <!-- ****************************************** robot arm END ******************************************************** -->

</robot>
