<?xml version="1.0"?>
<robot name="assembly">

  <link name="tron1computer">
    <visual>
      <origin xyz="0 0 0" rpy="0 0 0" />
      <geometry>
        <mesh filename="meshes/miniPC_urdf.STL" />
      </geometry>
      <material name="comp_tron1computer_base_link_mat">
        <color rgba="0.69804314 0.69804314 0.69804314 1.00000000"/>
      </material>
    </visual>
    <collision>
      <origin xyz="0 0 0" rpy="0 0 0" />
      <geometry>
        <mesh filename="meshes/miniPC_urdf.STL" />
      </geometry>
    </collision>
    <inertial>
      <origin xyz="0.020005 0.00075 0.051839" rpy="0 0 0" />
      <mass value="2.139" />
      <inertia ixx="0.0058901" ixy="-0.0000303" ixz="0.0001477" iyy="0.0093537" iyz="-0.000011" izz="0.0117309" />
    </inertial>
  </link>

  <link name="base_link">
      <inertial>
          <origin xyz="-0.00013359 6.672E-05 0.031672" rpy="0 0 0" />
          <mass value="0.42272" />
          <inertia
              ixx="0.00060728"
              ixy="3.437e-7"
              ixz="9.790e-7"
              iyy="0.00060832"
              iyz="-1.696e-6"
              izz="1.917e-4" />
      </inertial>
      <visual>
          <origin xyz="0 0 0" rpy="0 0 0" />
          <geometry>
              <mesh filename="models/meshes/L5_umi/arm/raw_meshes_ARM/base_link_arm.STL" />
          </geometry>
          <material name="">
              <color rgba="0.89804 0.91765 0.92941 1" />
          </material>
      </visual>
      <collision>
          <origin xyz="0 0 0" rpy="0 0 0" />
          <geometry>
              <mesh filename="models/meshes/L5_umi/arm/raw_meshes_ARM/base_link_arm.STL" />
          </geometry>
      </collision>
  </link>
  <link name="link1">
      <inertial>
          <origin xyz="0.005056 -0.0078534 0.020887" rpy="0 0 0" />
          <mass value="0.09728" />
          <inertia ixx="0.00011" ixy="-0.00001" ixz="0.00001" iyy="0.00005" iyz="-0.00001"
              izz="0.00010" />
      </inertial>
      <visual>
          <origin xyz="0 0 0" rpy="0 0 0" />
          <geometry>
              <mesh filename="models/meshes/L5_umi/arm/raw_meshes_ARM/link1.STL" />
          </geometry>
          <material name="">
              <color rgba="0.56471 0.56471 0.56471 1" />
          </material>
      </visual>
      <collision>
          <origin xyz="0 0 0" rpy="0 0 0" />
          <geometry>
              <mesh filename="models/meshes/L5_umi/arm/raw_meshes_ARM/link1.STL" />
          </geometry>
      </collision>
  </link>
  <joint name="J1" type="revolute">
      <origin xyz="0 0 0.0565" rpy="0 0 0" />
      <parent link="base_link" />
      <child link="link1" />
      <axis xyz="0 0 1" />
      <limit lower="-3.14" upper="2.618" effort="30" velocity="5" />
  </joint>
  <link name="link2">
      <inertial>
          <origin xyz="-0.12983 -0.00073729 -1.2236E-05" rpy="0 0 0" />
          <mass value="1.1477" />
          <inertia ixx="0.00057063"
              ixy="0.00011251"
              ixz="0.00001979"
              iyy="0.03669927"
              iyz="1.203e-8"
              izz="0.03683489" />
      </inertial>
      <visual>
          <origin xyz="0 0 0" rpy="0 0 0" />
          <geometry>
              <mesh filename="models/meshes/L5_umi/arm/raw_meshes_ARM/link2.STL" />
          </geometry>
          <material name="">
              <color rgba="0.69804 0.69804 0.69804 1" />
          </material>
      </visual>
      <collision>
          <origin xyz="0 0 0" rpy="0 0 0" />
          <geometry>
              <mesh filename="models/meshes/L5_umi/arm/raw_meshes_ARM/link2.STL" />
          </geometry>
      </collision>
  </link>
  <joint name="J2" type="revolute">
      <origin xyz="0.02 0 0.047" rpy="0 0 0" />
      <parent link="link1" />
      <child link="link2" />
      <axis xyz="0 1 0" />
      <limit lower="-0.05" upper="3.50" effort="40" velocity="5" />
  </joint>
  <link name="link3">
      <inertial>
          <origin xyz="0.15404 5.5044E-07 -0.054689" rpy="0 0 0" />
          <mass value="0.66" />
          <inertia ixx="0.00178249"
              ixy="-0.00003986"
              ixz="0.00571"
              iyy="0.02486615"
              iyz="1.346e-5"
              izz="0.02329476" />
      </inertial>
      <visual>
          <origin xyz="0 0 0" rpy="0 0 0" />
          <geometry>
              <mesh filename="models/meshes/L5_umi/arm/raw_meshes_ARM/link3.STL" />
          </geometry>
          <material name="">
              <color rgba="0.89804 0.91765 0.92941 1" />
          </material>
      </visual>
      <collision>
          <origin xyz="0 0 0" rpy="0 0 0" />
          <geometry>
              <mesh filename="models/meshes/L5_umi/arm/raw_meshes_ARM/link3.STL" />
          </geometry>
      </collision>
  </link>
  <joint name="J3" type="revolute">
      <origin xyz="-0.264 0 0" rpy="3.1416 0 0" />
      <parent link="link2" />
      <child link="link3" />
      <axis xyz="0 1 0" />
      <limit lower="-0.1" upper="3.2" effort="30" velocity="5.5" />
  </joint>
  <link name="link4">
      <inertial>
          <origin xyz="0.040231 0.0039307 -0.035335" rpy="0 0 0" />
          <mass value="0.11714" />
          <inertia ixx="0.00017832"
              ixy="0.00001697"
              ixz="0.0000776"
              iyy="0.00021182"
              iyz="-0.00001779"
              izz="0.00011328" />
      </inertial>
      <visual>
          <origin xyz="0 0 0" rpy="0 0 0" />
          <geometry>
              <mesh filename="models/meshes/L5_umi/arm/raw_meshes_ARM/link4.STL" />
          </geometry>
          <material name="">
              <color rgba="0.56471 0.56471 0.56471 1" />
          </material>
      </visual>
      <collision>
          <origin xyz="0 0 0" rpy="0 0 0" />
          <geometry>
              <mesh filename="models/meshes/L5_umi/arm/raw_meshes_ARM/link4.STL" />
          </geometry>
      </collision>
  </link>
  <joint name="J4" type="revolute">
      <origin xyz="0.245 0 -0.06" rpy="0 0 0" />
      <parent link="link3" />
      <child link="link4" />
      <axis xyz="0 1 0" />
      <limit lower="-1.6" upper="1.55" effort="15" velocity="5.5" />
  </joint>
  <link name="link5">
      <inertial>
          <origin xyz="0.0036004 -1.5445E-05 0.055255" rpy="0 0 0" />
          <mass value="0.6353" />
          <inertia ixx="0.00254972"
              ixy="2.600e-7"
              ixz="-0.00021534"
              iyy="0.00255018"
              iyz="-5.980e-7"
              izz="0.00026961" />
      </inertial>
      <visual>
          <origin xyz="0 0 0" rpy="0 0 0" />
          <geometry>
              <mesh filename="models/meshes/L5_umi/arm/raw_meshes_ARM/link5.STL" />
          </geometry>
          <material name="">
              <color rgba="0.69804 0.69804 0.69804 1" />
          </material>
      </visual>
      <collision>
          <origin xyz="0 0 0" rpy="0 0 0" />
          <geometry>
              <mesh filename="models/meshes/L5_umi/arm/raw_meshes_ARM/link5.STL" />
          </geometry>
      </collision>
  </link>
  <joint name="J5" type="revolute">
      <origin xyz="0.06775 -5E-05 -0.0865" rpy="0 0 0" />
      <parent link="link4" />
      <child link="link5" />
      <axis xyz="0 0 1" />
      <limit lower="-1.57" upper="1.57" effort="10" velocity="5" />
  </joint>
  <link name="link6">
      <inertial>
          <origin xyz="0.050676 -4.9137E-05 5.123E-05" rpy="0 0 0" />
          <mass value="0.902" />
          <inertia ixx="0.00029" ixy="0.00000" ixz="0.00000" iyy="0.00028" iyz="-0.00001"
              izz="0.00045" />
      </inertial>
      <visual>
          <origin xyz="0 -0.0225 -0.0225" rpy="1.5707963 0 1.5707963" />
          <geometry>
              <mesh filename="models/meshes/DAS_Controller_v3_r5_end_adapter_flange.STL" scale="0.001 0.001 0.001" />
          </geometry>
          <material name="">
              <color rgba="0.89804 0.91765 0.92941 1" />
          </material>
      </visual>
      <collision>
          <origin xyz="0 -0.0225 -0.0225" rpy="1.5707963 0 1.5707963" />
          <geometry>
              <mesh filename="models/meshes/DAS_Controller_v3_r5_end_adapter_flange.STL" scale="0.001 0.001 0.001" />
          </geometry>
      </collision>
      <visual>
          <origin xyz="0.0091 0 0" rpy="0 0 0" />
          <geometry>
              <mesh filename="models/meshes/L5_umi/umi/link_Flange.STL" />
          </geometry>
          <material name="">
              <color rgba="0.89804 0.91765 0.92941 1" />
          </material>
      </visual>
      <collision>
          <origin xyz="0.0091 0 0" rpy="0 0 0" />
          <geometry>
              <mesh filename="models/meshes/L5_umi/umi/link_Flange.STL" />
          </geometry>
      </collision>
      <visual>
          <origin xyz="0.0999414 0.0000388 0.0767217" rpy="0 0.2618 0" />
          <geometry>
              <mesh filename="models/meshes/L5_umi/umi/base_link.STL" />
          </geometry>
          <material name="">
              <color rgba="1 1 1 1" />
          </material>
      </visual>
      <collision>
          <origin xyz="0.0999414 0.0000388 0.0767217" rpy="0 0.2618 0" />
          <geometry>
              <mesh filename="models/meshes/L5_umi/umi/base_link.STL" />
          </geometry>
      </collision>
      <visual>
          <origin xyz="0.1066203 0.0429998 0.0136096" rpy="0 0 0" />
          <geometry>
              <mesh filename="models/meshes/L5_umi/umi/link1.STL" />
          </geometry>
          <material name="">
              <color rgba="1 1 1 1" />
          </material>
      </visual>
      <collision>
          <origin xyz="0.1066203 0.0429998 0.0136096" rpy="0 0 0" />
          <geometry>
              <mesh filename="models/meshes/L5_umi/umi/link1.STL" />
          </geometry>
      </collision>
      <visual>
          <origin xyz="0.1498023 0.0887898 0.0136095" rpy="0 0 0" />
          <geometry>
              <mesh filename="models/meshes/L5_umi/umi/link3.STL" />
          </geometry>
          <material name="">
              <color rgba="0.498039 0.498039 0.498039 1" />
          </material>
      </visual>
      <collision>
          <origin xyz="0.1498023 0.0887898 0.0136095" rpy="0 0 0" />
          <geometry>
              <mesh filename="models/meshes/L5_umi/umi/link3.STL" />
          </geometry>
      </collision>
      <visual>
          <origin xyz="0.1066203 -0.0430002 0.0136096" rpy="0 0 0" />
          <geometry>
              <mesh filename="models/meshes/L5_umi/umi/link2.STL" />
          </geometry>
          <material name="">
              <color rgba="0.792157 0.819608 0.933333 1" />
          </material>
      </visual>
      <collision>
          <origin xyz="0.1066203 -0.0430002 0.0136096" rpy="0 0 0" />
          <geometry>
              <mesh filename="models/meshes/L5_umi/umi/link2.STL" />
          </geometry>
      </collision>
      <visual>
          <origin xyz="0.1498023 -0.0887902 0.0136095" rpy="0 0 0" />
          <geometry>
              <mesh filename="models/meshes/L5_umi/umi/link4.STL" />
          </geometry>
          <material name="">
              <color rgba="0.498039 0.498039 0.498039 1" />
          </material>
      </visual>
      <collision>
          <origin xyz="0.1498023 -0.0887902 0.0136095" rpy="0 0 0" />
          <geometry>
              <mesh filename="models/meshes/L5_umi/umi/link4.STL" />
          </geometry>
      </collision>
      <visual>
          <origin xyz="0.1218700 0.0195168 0.0136097" rpy="0 0 0" />
          <geometry>
              <mesh filename="models/meshes/L5_umi/umi/link5.STL" />
          </geometry>
          <material name="">
              <color rgba="0.796078 0.823529 0.937255 1" />
          </material>
      </visual>
      <collision>
          <origin xyz="0.1218700 0.0195168 0.0136097" rpy="0 0 0" />
          <geometry>
              <mesh filename="models/meshes/L5_umi/umi/link5.STL" />
          </geometry>
      </collision>
      <visual>
          <origin xyz="0.1218700 -0.0195172 0.0136097" rpy="0 0 0" />
          <geometry>
              <mesh filename="models/meshes/L5_umi/umi/link6.STL" />
          </geometry>
          <material name="">
              <color rgba="0.796078 0.823529 0.937255 1" />
          </material>
      </visual>
      <collision>
          <origin xyz="0.1218700 -0.0195172 0.0136097" rpy="0 0 0" />
          <geometry>
              <mesh filename="models/meshes/L5_umi/umi/link6.STL" />
          </geometry>
      </collision>
  </link>
  <joint name="J6" type="revolute">
      <origin xyz="0.02895 0 0.0865" rpy="3.1416 0 0" />
      <parent link="link5" />
      <child link="link6" />
      <axis xyz="1 0 0" />
      <limit lower="-2" upper="2" effort="10" velocity="5" />
  </joint>

  <link name="eef_link">
      <inertial>
          <!-- Valid, dynamically negligible mass avoids PhysX inventing an
               engine-dependent fallback inertia for this marker frame. -->
          <mass value="0.000001" />
          <origin xyz="0.0 0.0 0.0" rpy="0 0 0" />
          <inertia ixx="1e-12" ixy="0.0" ixz="0.0" iyy="1e-12" iyz="0.0" izz="1e-12" />
      </inertial>
  </link>

  <joint name="gripper_fixed_joint" type="fixed">
      <origin xyz="0.15 0 0" rpy="0 0 0" />
      <parent link="link6" />
      <child link="eef_link" />
  </joint>

  <link name="base_Link">
    <visual>
      <origin xyz="0 0 0" rpy="0 0 0" />
      <geometry>
        <mesh filename="meshes/base_Link.STL" />
      </geometry>
      <material name="comp_base_Link_base_Link_mat">
        <color rgba="0.79216078 0.81961176 0.92941569 1.00000000"/>
      </material>
    </visual>
    <collision>
      <origin xyz="0.03 0 -0.072" rpy="0 0 0" />
      <geometry>
        <box size="0.27 0.26 0.19" />
      </geometry>
    </collision>
    <inertial>
      <origin xyz="0.04576 0.00014 -0.16398" rpy="0 0 0" />
      <mass value="9.585" />
      <inertia ixx="0.1401105" ixy="0.0005349" ixz="0.0281841" iyy="0.1106414" iyz="-0.0000273" izz="0.0989445" />
    </inertial>
  </link>

  <link name="limx_imu">
    <visual>
      <origin xyz="0 0 0" rpy="0 0 0" />
      <geometry>
        <box size="0.015 0.015 0.004" />
      </geometry>
      <material name="comp_limx_imu_mat">
        <color rgba="1.00000000 0.64706275 0.00000392 1.00000000"/>
      </material>
    </visual>
    <inertial>
      <origin xyz="0 0 0" rpy="0 0 0" />
      <mass value="0.01" />
      <inertia ixx="0.000001" ixy="0" ixz="0" iyy="0.000001" iyz="0" izz="0.000001" />
    </inertial>
  </link>

  <link name="abad_L_Link">
    <visual>
      <origin xyz="0 0 0" rpy="0 0 0" />
      <geometry>
        <mesh filename="meshes/abad_L_Link.STL" />
      </geometry>
      <material name="comp_abad_L_Link_mat">
        <color rgba="0.79216078 0.81961176 0.92941569 1.00000000"/>
      </material>
    </visual>
    <collision>
      <origin xyz="0.03 0 0" rpy="1.57 0 1.57" />
      <geometry>
        <cylinder radius="0.05" length="0.05" />
      </geometry>
    </collision>
    <inertial>
      <origin xyz="-0.06977 0.04479 0.00057" rpy="0 0 0" />
      <mass value="1.469" />
      <inertia ixx="0.0015554" ixy="0.0003978" ixz="-0.0000131" iyy="0.0023592" iyz="-0.000001" izz="0.0020809" />
    </inertial>
  </link>

  <link name="hip_L_Link">
    <visual>
      <origin xyz="0 0 0" rpy="0 0 0" />
      <geometry>
        <mesh filename="meshes/hip_L_Link.STL" />
      </geometry>
      <material name="comp_hip_L_Link_mat">
        <color rgba="1.00000000 1.00000000 1.00000000 1.00000000"/>
      </material>
    </visual>
    <collision>
      <origin xyz="-0.1 -0.03 -0.14" rpy="0 0.53 0" />
      <geometry>
        <cylinder radius="0.035" length="0.15" />
      </geometry>
    </collision>
    <inertial>
      <origin xyz="-0.02869 -0.0477 -0.03992" rpy="0 0 0" />
      <mass value="2.3" />
      <inertia ixx="0.0169373" ixy="0.001647" ixz="-0.0092325" iyy="0.0228533" iyz="0.0022024" izz="0.0093342" />
    </inertial>
  </link>

  <link name="knee_L_Link">
    <visual>
      <origin xyz="0 0 0" rpy="0 0 0" />
      <geometry>
        <mesh filename="meshes/knee_L_Link.STL" />
      </geometry>
      <material name="comp_knee_L_Link_mat">
        <color rgba="0.79216078 0.81961176 0.92941569 1.00000000"/>
      </material>
    </visual>
    <collision>
      <origin xyz="0.078 0 -0.12" rpy="0 -0.55 0" />
      <geometry>
        <cylinder radius="0.02" length="0.26" />
      </geometry>
    </collision>
    <inertial>
      <origin xyz="0.11452 0.0013 -0.19367" rpy="0 0 0" />
      <mass value="1.22" />
      <inertia ixx="0.0109384" ixy="-0.0000079" ixz="0.0059865" iyy="0.0143581" iyz="0.0000101" izz="0.0040876" />
    </inertial>
  </link>

  <link name="ankle_L_Link">
    <visual>
      <origin xyz="0 0 0" rpy="0 0 0" />
      <geometry>
        <mesh filename="meshes/ankle_L_Link.STL" />
      </geometry>
      <material name="comp_ankle_L_Link_mat">
        <color rgba="0.26667059 0.26667059 0.26667059 1.00000000"/>
      </material>
    </visual>
    <collision>
      <origin xyz="0 0 0" rpy="0 0 0" />
      <geometry>
        <mesh filename="meshes/ankle_L_Link.STL" />
      </geometry>
    </collision>
    <inertial>
      <origin xyz="0.01074 -0.00061 -0.03314" rpy="0 0 0" />
      <mass value="0.62" />
      <inertia ixx="0.0005255" ixy="-0.0000035" ixz="-0.0000514" iyy="0.001812" iyz="0.0000065" izz="0.0019738" />
    </inertial>
  </link>

  <link name="abad_R_Link">
    <visual>
      <origin xyz="0 0 0" rpy="0 0 0" />
      <geometry>
        <mesh filename="meshes/abad_R_Link.STL" />
      </geometry>
      <material name="comp_abad_R_Link_mat">
        <color rgba="0.79216078 0.81961176 0.92941569 1.00000000"/>
      </material>
    </visual>
    <collision>
      <origin xyz="0.03 0 0" rpy="1.57 0 1.57" />
      <geometry>
        <cylinder radius="0.05" length="0.05" />
      </geometry>
    </collision>
    <inertial>
      <origin xyz="-0.06977 -0.04479 0.00057" rpy="0 0 0" />
      <mass value="1.469" />
      <inertia ixx="0.0015554" ixy="-0.0003978" ixz="-0.0000131" iyy="0.0023592" iyz="0.000001" izz="0.0020809" />
    </inertial>
  </link>

  <link name="hip_R_Link">
    <visual>
      <origin xyz="0 0 0" rpy="0 0 0" />
      <geometry>
        <mesh filename="meshes/hip_R_Link.STL" />
      </geometry>
      <material name="comp_hip_R_Link_mat">
        <color rgba="1.00000000 1.00000000 1.00000000 1.00000000"/>
      </material>
    </visual>
    <collision>
      <origin xyz="-0.1 0.03 -0.14" rpy="0 0.53 0" />
      <geometry>
        <cylinder radius="0.035" length="0.15" />
      </geometry>
    </collision>
    <inertial>
      <origin xyz="-0.02869 0.0477 -0.03992" rpy="0 0 0" />
      <mass value="2.3" />
      <inertia ixx="0.0169373" ixy="-0.001647" ixz="-0.0092325" iyy="0.0228533" iyz="-0.0022024" izz="0.0093342" />
    </inertial>
  </link>

  <link name="knee_R_Link">
    <visual>
      <origin xyz="0 0 0" rpy="0 0 0" />
      <geometry>
        <mesh filename="meshes/knee_R_Link.STL" />
      </geometry>
      <material name="comp_knee_R_Link_mat">
        <color rgba="0.79216078 0.81961176 0.92941569 1.00000000"/>
      </material>
    </visual>
    <collision>
      <origin xyz="0.078 0 -0.12" rpy="0 -0.55 0" />
      <geometry>
        <cylinder radius="0.02" length="0.26" />
      </geometry>
    </collision>
    <inertial>
      <origin xyz="0.11452 -0.0013 -0.19367" rpy="0 0 0" />
      <mass value="1.22" />
      <inertia ixx="0.0109384" ixy="0.0000079" ixz="0.0059865" iyy="0.0143581" iyz="-0.0000101" izz="0.0040876" />
    </inertial>
  </link>

  <link name="ankle_R_Link">
    <visual>
      <origin xyz="0 0 0" rpy="0 0 0" />
      <geometry>
        <mesh filename="meshes/ankle_R_Link.STL" />
      </geometry>
      <material name="comp_ankle_R_Link_mat">
        <color rgba="0.26667059 0.26667059 0.26667059 1.00000000"/>
      </material>
    </visual>
    <collision>
      <origin xyz="0 0 0" rpy="0 0 0" />
      <geometry>
        <mesh filename="meshes/ankle_R_Link.STL" />
      </geometry>
    </collision>
    <inertial>
      <origin xyz="0.01074 0.00061 -0.03314" rpy="0 0 0" />
      <mass value="0.62" />
      <inertia ixx="0.0005255" ixy="0.0000035" ixz="-0.0000514" iyy="0.001812" iyz="-0.0000065" izz="0.0019738" />
    </inertial>
  </link>

  <joint name="limx_imu_joint" type="fixed">
    <parent link="base_Link" />
    <child link="limx_imu" />
    <origin xyz="0 0 0" rpy="0 0 0" />
  </joint>

  <joint name="abad_L_Joint" type="revolute">
    <parent link="base_Link" />
    <child link="abad_L_Link" />
    <origin xyz="0.05556 0.105 -0.2602" rpy="0 0 0" />
    <axis xyz="1 0 0" />
    <limit lower="-0.38397" upper="1.39626" effort="80" velocity="15" />
  </joint>

  <joint name="hip_L_Joint" type="revolute">
    <parent link="abad_L_Link" />
    <child link="hip_L_Link" />
    <origin xyz="-0.077 0.0205 0" rpy="0 0 0" />
    <axis xyz="0 1 0" />
    <limit lower="-1.012291" upper="1.396263" effort="80" velocity="15" />
  </joint>

  <joint name="knee_L_Joint" type="revolute">
    <parent link="hip_L_Link" />
    <child link="knee_L_Link" />
    <origin xyz="-0.15 -0.0205 -0.25981" rpy="0 0 0" />
    <axis xyz="0 -1 0" />
    <limit lower="-0.872665" upper="1.361357" effort="80" velocity="15" />
  </joint>

  <joint name="ankle_L_Joint" type="revolute">
    <parent link="knee_L_Link" />
    <child link="ankle_L_Link" />
    <origin xyz="0.15 0 -0.25981" rpy="0 0 0" />
    <axis xyz="0 -1 0" />
    <limit lower="-1.1519173" upper="1.5707963" effort="20" velocity="15" />
    <dynamics damping="0" friction="0.01" />
  </joint>

  <joint name="abad_R_Joint" type="revolute">
    <parent link="base_Link" />
    <child link="abad_R_Link" />
    <origin xyz="0.05556 -0.105 -0.2602" rpy="0 0 0" />
    <axis xyz="1 0 0" />
    <limit lower="-1.39626" upper="0.38397" effort="80" velocity="15" />
  </joint>

  <joint name="hip_R_Joint" type="revolute">
    <parent link="abad_R_Link" />
    <child link="hip_R_Link" />
    <origin xyz="-0.077 -0.0205 0" rpy="0 0 0" />
    <axis xyz="0 -1 0" />
    <limit lower="-1.396263" upper="1.012291" effort="80" velocity="15" />
  </joint>

  <joint name="knee_R_Joint" type="revolute">
    <parent link="hip_R_Link" />
    <child link="knee_R_Link" />
    <origin xyz="-0.15 0.0205 -0.25981" rpy="0 0 0" />
    <axis xyz="0 1 0" />
    <limit lower="-1.361357" upper="0.872665" effort="80" velocity="15" />
  </joint>

  <joint name="ankle_R_Joint" type="revolute">
    <parent link="knee_R_Link" />
    <child link="ankle_R_Link" />
    <origin xyz="0.15 0 -0.25981" rpy="0 0 0" />
    <axis xyz="0 -1 0" />
    <limit lower="-1.1519173" upper="1.5707963" effort="20" velocity="15" />
    <dynamics damping="0" friction="0.01" />
  </joint>

  <joint name="base_Link-tron1computer" type="fixed">
    <parent link="base_Link" />
    <child link="tron1computer" />
    <origin xyz="0 0 0.0163" rpy="0 0 0" />
  </joint>

  <joint name="tron1computer-assembly" type="fixed">
    <parent link="tron1computer" />
    <child link="base_link" />
    <origin xyz="0 0 0.096" rpy="0 0 0" />
  </joint>

</robot>
