<?xml version='1.0' encoding='utf-8'?>
<mujoco model="assembly">
  <compiler angle="radian" meshdir="meshes" autolimits="true" inertiafromgeom="false" />
  <option timestep="0.001" />
  <size njmax="500" nconmax="200" nuser_jnt="1" />
  <default>
    <default class="visual">
      <geom contype="0" conaffinity="0" group="2" density="0" />
    </default>
    <default class="collision">
      <geom contype="1" conaffinity="1" group="3" condim="3" rgba="0.5 0.6 0.7 0" margin="0.001" />
    </default>
  </default>
  <asset>
    <mesh name="urdf_models_meshes_L5_umi_arm_raw_meshes_ARM_base_link_arm" file="../models/meshes/L5_umi/arm/raw_meshes_ARM/base_link_arm.STL" />
    <mesh name="urdf_models_meshes_L5_umi_arm_raw_meshes_ARM_link1" file="../models/meshes/L5_umi/arm/raw_meshes_ARM/link1.STL" />
    <mesh name="urdf_models_meshes_L5_umi_arm_raw_meshes_ARM_link2" file="../models/meshes/L5_umi/arm/raw_meshes_ARM/link2.STL" />
    <mesh name="urdf_models_meshes_L5_umi_arm_raw_meshes_ARM_link3" file="../models/meshes/L5_umi/arm/raw_meshes_ARM/link3.STL" />
    <mesh name="urdf_models_meshes_L5_umi_arm_raw_meshes_ARM_link4" file="../models/meshes/L5_umi/arm/raw_meshes_ARM/link4.STL" />
    <mesh name="urdf_models_meshes_L5_umi_arm_raw_meshes_ARM_link5" file="../models/meshes/L5_umi/arm/raw_meshes_ARM/link5.STL" />
    <mesh name="urdf_models_meshes_DAS_Controller_v3_r5_end_adapter_flange" file="../models/meshes/DAS_Controller_v3_r5_end_adapter_flange.STL" scale="0.001 0.001 0.001" />
    <mesh name="urdf_models_meshes_L5_umi_umi_link_Flange" file="../models/meshes/L5_umi/umi/link_Flange.STL" />
    <mesh name="urdf_models_meshes_L5_umi_umi_base_link" file="../models/meshes/L5_umi/umi/base_link.STL" />
    <mesh name="urdf_models_meshes_L5_umi_umi_link1" file="../models/meshes/L5_umi/umi/link1.STL" />
    <mesh name="urdf_models_meshes_L5_umi_umi_link3" file="../models/meshes/L5_umi/umi/link3.STL" />
    <mesh name="urdf_models_meshes_L5_umi_umi_link2" file="../models/meshes/L5_umi/umi/link2.STL" />
    <mesh name="urdf_models_meshes_L5_umi_umi_link4" file="../models/meshes/L5_umi/umi/link4.STL" />
    <mesh name="urdf_models_meshes_L5_umi_umi_link5" file="../models/meshes/L5_umi/umi/link5.STL" />
    <mesh name="urdf_models_meshes_L5_umi_umi_link6" file="../models/meshes/L5_umi/umi/link6.STL" />
    <mesh name="base_Link" file="base_Link.STL" />
    <mesh name="abad_L_Link" file="abad_L_Link.STL" />
    <mesh name="hip_L_Link" file="hip_L_Link.STL" />
    <mesh name="knee_L_Link" file="knee_L_Link.STL" />
    <mesh name="ankle_L_Link" file="ankle_L_Link.STL" />
    <mesh name="abad_R_Link" file="abad_R_Link.STL" />
    <mesh name="hip_R_Link" file="hip_R_Link.STL" />
    <mesh name="knee_R_Link" file="knee_R_Link.STL" />
    <mesh name="ankle_R_Link" file="ankle_R_Link.STL" />
    <mesh name="miniPC_urdf_01" file="mjcf/miniPC_urdf_01.STL" />
    <mesh name="miniPC_urdf_02" file="mjcf/miniPC_urdf_02.STL" />
    <mesh name="miniPC_urdf_03" file="mjcf/miniPC_urdf_03.STL" />
    <mesh name="miniPC_urdf_04" file="mjcf/miniPC_urdf_04.STL" />
    <mesh name="miniPC_urdf_05" file="mjcf/miniPC_urdf_05.STL" />
    <mesh name="miniPC_urdf_06" file="mjcf/miniPC_urdf_06.STL" />
    <mesh name="miniPC_urdf_07" file="mjcf/miniPC_urdf_07.STL" />
    <mesh name="miniPC_urdf_08" file="mjcf/miniPC_urdf_08.STL" />
  </asset>
  <worldbody>
    <body name="base_Link">
      <freejoint name="root" />
      <inertial mass="9.585" pos="0.04576 0.00014 -0.16398" fullinertia="0.1401105 0.1106414 0.0989445 0.0005349 0.0281841 -0.0000273" />
      <geom name="base_Link_visual_1" class="visual" rgba="0.79216078 0.81961176 0.92941569 1.00000000" type="mesh" mesh="base_Link" />
      <geom name="base_Link_collision_1" class="collision" pos="0.03 0 -0.072" type="box" size="0.135 0.13 0.095" />
      <body name="limx_imu">
        <inertial mass="0.01" fullinertia="0.000001 0.000001 0.000001 0 0 0" pos="0 0 0" />
        <geom name="limx_imu_visual_1" class="visual" rgba="1.00000000 0.64706275 0.00000392 1.00000000" type="box" size="0.0075 0.0075 0.002" />
        <site name="imu" pos="0 0 0" size="0.005" />
      </body>
      <body name="abad_L_Link" pos="0.05556 0.105 -0.2602">
        <inertial mass="1.469" pos="-0.06977 0.04479 0.00057" fullinertia="0.0015554 0.0023592 0.0020809 0.0003978 -0.0000131 -0.000001" />
        <joint name="abad_L_Joint" type="hinge" axis="1 0 0" limited="true" range="-0.38397 1.39626" actuatorfrclimited="true" actuatorfrcrange="-80 80" user="15" />
        <geom name="abad_L_Link_visual_1" class="visual" rgba="0.79216078 0.81961176 0.92941569 1.00000000" type="mesh" mesh="abad_L_Link" />
        <geom name="abad_L_Link_collision_1" class="collision" pos="0.03 0 0" quat="0.500398163355 0.499999841466 0.499601836645 0.499999841466" type="cylinder" size="0.05 0.025" />
        <body name="hip_L_Link" pos="-0.077 0.0205 0">
          <inertial mass="2.3" pos="-0.02869 -0.0477 -0.03992" fullinertia="0.0169373 0.0228533 0.0093342 0.001647 -0.0092325 0.0022024" />
          <joint name="hip_L_Joint" type="hinge" axis="0 1 0" limited="true" range="-1.012291 1.396263" actuatorfrclimited="true" actuatorfrcrange="-80 80" user="15" />
          <geom name="hip_L_Link_visual_1" class="visual" rgba="1.00000000 1.00000000 1.00000000 1.00000000" type="mesh" mesh="hip_L_Link" />
          <geom name="hip_L_Link_collision_1" class="collision" pos="-0.1 -0.03 -0.14" quat="0.965092500881 0 0.26190926815 0" type="cylinder" size="0.035 0.075" />
          <body name="knee_L_Link" pos="-0.15 -0.0205 -0.25981">
            <inertial mass="1.22" pos="0.11452 0.0013 -0.19367" fullinertia="0.0109384 0.0143581 0.0040876 -0.0000079 0.0059865 0.0000101" />
            <joint name="knee_L_Joint" type="hinge" axis="0 -1 0" limited="true" range="-0.872665 1.361357" actuatorfrclimited="true" actuatorfrcrange="-80 80" user="15" />
            <geom name="knee_L_Link_visual_1" class="visual" rgba="0.79216078 0.81961176 0.92941569 1.00000000" type="mesh" mesh="knee_L_Link" />
            <geom name="knee_L_Link_collision_1" class="collision" pos="0.078 0 -0.12" quat="0.962425197628 0 -0.271546936956 0" type="cylinder" size="0.02 0.13" />
            <body name="ankle_L_Link" pos="0.15 0 -0.25981">
              <inertial mass="0.62" pos="0.01074 -0.00061 -0.03314" fullinertia="0.0005255 0.001812 0.0019738 -0.0000035 -0.0000514 0.0000065" />
              <joint name="ankle_L_Joint" type="hinge" axis="0 -1 0" limited="true" range="-1.1519173 1.5707963" actuatorfrclimited="true" actuatorfrcrange="-20 20" user="15" damping="0" frictionloss="0.01" />
              <geom name="ankle_L_Link_visual_1" class="visual" rgba="0.26667059 0.26667059 0.26667059 1.00000000" type="mesh" mesh="ankle_L_Link" />
              <geom name="ankle_L_Link_collision_1" class="collision" type="mesh" mesh="ankle_L_Link" />
            </body>
          </body>
        </body>
      </body>
      <body name="abad_R_Link" pos="0.05556 -0.105 -0.2602">
        <inertial mass="1.469" pos="-0.06977 -0.04479 0.00057" fullinertia="0.0015554 0.0023592 0.0020809 -0.0003978 -0.0000131 0.000001" />
        <joint name="abad_R_Joint" type="hinge" axis="1 0 0" limited="true" range="-1.39626 0.38397" actuatorfrclimited="true" actuatorfrcrange="-80 80" user="15" />
        <geom name="abad_R_Link_visual_1" class="visual" rgba="0.79216078 0.81961176 0.92941569 1.00000000" type="mesh" mesh="abad_R_Link" />
        <geom name="abad_R_Link_collision_1" class="collision" pos="0.03 0 0" quat="0.500398163355 0.499999841466 0.499601836645 0.499999841466" type="cylinder" size="0.05 0.025" />
        <body name="hip_R_Link" pos="-0.077 -0.0205 0">
          <inertial mass="2.3" pos="-0.02869 0.0477 -0.03992" fullinertia="0.0169373 0.0228533 0.0093342 -0.001647 -0.0092325 -0.0022024" />
          <joint name="hip_R_Joint" type="hinge" axis="0 -1 0" limited="true" range="-1.396263 1.012291" actuatorfrclimited="true" actuatorfrcrange="-80 80" user="15" />
          <geom name="hip_R_Link_visual_1" class="visual" rgba="1.00000000 1.00000000 1.00000000 1.00000000" type="mesh" mesh="hip_R_Link" />
          <geom name="hip_R_Link_collision_1" class="collision" pos="-0.1 0.03 -0.14" quat="0.965092500881 0 0.26190926815 0" type="cylinder" size="0.035 0.075" />
          <body name="knee_R_Link" pos="-0.15 0.0205 -0.25981">
            <inertial mass="1.22" pos="0.11452 -0.0013 -0.19367" fullinertia="0.0109384 0.0143581 0.0040876 0.0000079 0.0059865 -0.0000101" />
            <joint name="knee_R_Joint" type="hinge" axis="0 1 0" limited="true" range="-1.361357 0.872665" actuatorfrclimited="true" actuatorfrcrange="-80 80" user="15" />
            <geom name="knee_R_Link_visual_1" class="visual" rgba="0.79216078 0.81961176 0.92941569 1.00000000" type="mesh" mesh="knee_R_Link" />
            <geom name="knee_R_Link_collision_1" class="collision" pos="0.078 0 -0.12" quat="0.962425197628 0 -0.271546936956 0" type="cylinder" size="0.02 0.13" />
            <body name="ankle_R_Link" pos="0.15 0 -0.25981">
              <inertial mass="0.62" pos="0.01074 0.00061 -0.03314" fullinertia="0.0005255 0.001812 0.0019738 0.0000035 -0.0000514 -0.0000065" />
              <joint name="ankle_R_Joint" type="hinge" axis="0 -1 0" limited="true" range="-1.1519173 1.5707963" actuatorfrclimited="true" actuatorfrcrange="-20 20" user="15" damping="0" frictionloss="0.01" />
              <geom name="ankle_R_Link_visual_1" class="visual" rgba="0.26667059 0.26667059 0.26667059 1.00000000" type="mesh" mesh="ankle_R_Link" />
              <geom name="ankle_R_Link_collision_1" class="collision" type="mesh" mesh="ankle_R_Link" />
            </body>
          </body>
        </body>
      </body>
      <body name="tron1computer" pos="0 0 0.0163">
        <inertial mass="2.139" pos="0.020005 0.00075 0.051839" fullinertia="0.0058901 0.0093537 0.0117309 -0.0000303 0.0001477 -0.000011" />
        <geom name="tron1computer_visual_1_01" class="visual" rgba="0.69804314 0.69804314 0.69804314 1.00000000" type="mesh" mesh="miniPC_urdf_01" />
        <geom name="tron1computer_visual_1_02" class="visual" rgba="0.69804314 0.69804314 0.69804314 1.00000000" type="mesh" mesh="miniPC_urdf_02" />
        <geom name="tron1computer_visual_1_03" class="visual" rgba="0.69804314 0.69804314 0.69804314 1.00000000" type="mesh" mesh="miniPC_urdf_03" />
        <geom name="tron1computer_visual_1_04" class="visual" rgba="0.69804314 0.69804314 0.69804314 1.00000000" type="mesh" mesh="miniPC_urdf_04" />
        <geom name="tron1computer_visual_1_05" class="visual" rgba="0.69804314 0.69804314 0.69804314 1.00000000" type="mesh" mesh="miniPC_urdf_05" />
        <geom name="tron1computer_visual_1_06" class="visual" rgba="0.69804314 0.69804314 0.69804314 1.00000000" type="mesh" mesh="miniPC_urdf_06" />
        <geom name="tron1computer_visual_1_07" class="visual" rgba="0.69804314 0.69804314 0.69804314 1.00000000" type="mesh" mesh="miniPC_urdf_07" />
        <geom name="tron1computer_visual_1_08" class="visual" rgba="0.69804314 0.69804314 0.69804314 1.00000000" type="mesh" mesh="miniPC_urdf_08" />
        <geom name="tron1computer_collision_1_01" class="collision" type="mesh" mesh="miniPC_urdf_01" />
        <geom name="tron1computer_collision_1_02" class="collision" type="mesh" mesh="miniPC_urdf_02" />
        <geom name="tron1computer_collision_1_03" class="collision" type="mesh" mesh="miniPC_urdf_03" />
        <geom name="tron1computer_collision_1_04" class="collision" type="mesh" mesh="miniPC_urdf_04" />
        <geom name="tron1computer_collision_1_05" class="collision" type="mesh" mesh="miniPC_urdf_05" />
        <geom name="tron1computer_collision_1_06" class="collision" type="mesh" mesh="miniPC_urdf_06" />
        <geom name="tron1computer_collision_1_07" class="collision" type="mesh" mesh="miniPC_urdf_07" />
        <geom name="tron1computer_collision_1_08" class="collision" type="mesh" mesh="miniPC_urdf_08" />
        <body name="base_link_arm" pos="0 0 0.096">
          <inertial mass="0.42272" pos="-0.00013359 6.672e-05 0.031672" fullinertia="0.00060728 0.00060832 1.917e-4 3.437e-7 9.790e-7 -1.696e-6" />
          <geom name="base_link_arm_visual_1" class="visual" type="mesh" mesh="urdf_models_meshes_L5_umi_arm_raw_meshes_ARM_base_link_arm" rgba="0.89804 0.91765 0.92941 1" />
          <geom name="base_link_arm_collision_1" class="collision" type="mesh" mesh="urdf_models_meshes_L5_umi_arm_raw_meshes_ARM_base_link_arm" />
          <body name="link1" pos="0 0 0.0565">
            <inertial mass="0.09728" pos="0.005056 -0.0078534 0.020887" fullinertia="0.00011 0.00005 0.00010 -0.00001 0.00001 -0.00001" />
            <joint name="J1" type="hinge" axis="0 0 1" limited="true" range="-10 10" actuatorfrclimited="true" actuatorfrcrange="-100 100" />
            <geom name="link1_visual_1" class="visual" type="mesh" mesh="urdf_models_meshes_L5_umi_arm_raw_meshes_ARM_link1" rgba="0.56471 0.56471 0.56471 1" />
            <geom name="link1_collision_1" class="collision" type="mesh" mesh="urdf_models_meshes_L5_umi_arm_raw_meshes_ARM_link1" />
            <body name="link2" pos="0.02 0 0.047">
              <inertial mass="1.1477" pos="-0.12983 -0.00073729 -1.2236e-05" fullinertia="0.00057063 0.03669927 0.03683489 0.00011251 0.00001979 1.203e-8" />
              <joint name="J2" type="hinge" axis="0 1 0" limited="true" range="-10 10" actuatorfrclimited="true" actuatorfrcrange="-100 100" />
              <geom name="link2_visual_1" class="visual" type="mesh" mesh="urdf_models_meshes_L5_umi_arm_raw_meshes_ARM_link2" rgba="0.69804 0.69804 0.69804 1" />
              <geom name="link2_collision_1" class="collision" type="mesh" mesh="urdf_models_meshes_L5_umi_arm_raw_meshes_ARM_link2" />
              <body name="link3" pos="-0.264 0 0" quat="-3.67320510335e-06 0.999999999993 0 0">
                <inertial mass="0.66" pos="0.15404 5.5044e-07 -0.054689" fullinertia="0.00178249 0.02486615 0.02329476 -0.00003986 0.00571 1.346e-5" />
                <joint name="J3" type="hinge" axis="0 1 0" limited="true" range="-10 10" actuatorfrclimited="true" actuatorfrcrange="-100 100" />
                <geom name="link3_visual_1" class="visual" type="mesh" mesh="urdf_models_meshes_L5_umi_arm_raw_meshes_ARM_link3" rgba="0.89804 0.91765 0.92941 1" />
                <geom name="link3_collision_1" class="collision" type="mesh" mesh="urdf_models_meshes_L5_umi_arm_raw_meshes_ARM_link3" />
                <body name="link4" pos="0.245 0 -0.06">
                  <inertial mass="0.11714" pos="0.040231 0.0039307 -0.035335" fullinertia="0.00017832 0.00021182 0.00011328 0.00001697 0.0000776 -0.00001779" />
                  <joint name="J4" type="hinge" axis="0 1 0" limited="true" range="-10 10" actuatorfrclimited="true" actuatorfrcrange="-100 100" />
                  <geom name="link4_visual_1" class="visual" type="mesh" mesh="urdf_models_meshes_L5_umi_arm_raw_meshes_ARM_link4" rgba="0.56471 0.56471 0.56471 1" />
                  <geom name="link4_collision_1" class="collision" type="mesh" mesh="urdf_models_meshes_L5_umi_arm_raw_meshes_ARM_link4" />
                  <body name="link5" pos="0.06775 -5e-05 -0.0865">
                    <inertial mass="0.6353" pos="0.0036004 -1.5445e-05 0.055255" fullinertia="0.00254972 0.00255018 0.00026961 2.600e-7 -0.00021534 -5.980e-7" />
                    <joint name="J5" type="hinge" axis="0 0 1" limited="true" range="-10 10" actuatorfrclimited="true" actuatorfrcrange="-100 100" />
                    <geom name="link5_visual_1" class="visual" type="mesh" mesh="urdf_models_meshes_L5_umi_arm_raw_meshes_ARM_link5" rgba="0.69804 0.69804 0.69804 1" />
                    <geom name="link5_collision_1" class="collision" type="mesh" mesh="urdf_models_meshes_L5_umi_arm_raw_meshes_ARM_link5" />
                    <body name="link6" pos="0.02895 0 0.0865" quat="-3.67320510335e-06 0.999999999993 0 0">
                      <inertial mass="0.902" pos="0.050676 -4.9137e-05 5.123e-05" fullinertia="0.00029 0.00028 0.00045 0.00000 0.00000 -0.00001" />
                      <joint name="J6" type="hinge" axis="1 0 0" limited="true" range="-10 10" actuatorfrclimited="true" actuatorfrcrange="-100 100" />
                      <geom name="link6_visual_1" class="visual" type="mesh" mesh="urdf_models_meshes_DAS_Controller_v3_r5_end_adapter_flange" rgba="0.89804 0.91765 0.92941 1" pos="0 -0.0225 -0.0225" quat="0.500000013397 0.5 0.499999986603 0.5" />
                      <geom name="link6_visual_2" class="visual" type="mesh" mesh="urdf_models_meshes_L5_umi_umi_link_Flange" rgba="0.89804 0.91765 0.92941 1" pos="0.0091 0 0" />
                      <geom name="link6_visual_3" class="visual" type="mesh" mesh="urdf_models_meshes_L5_umi_umi_base_link" rgba="1 1 1 1" pos="0.0999414 3.88e-05 0.0767217" quat="0.99144482142 0 0.130526495702 0" />
                      <geom name="link6_visual_4" class="visual" type="mesh" mesh="urdf_models_meshes_L5_umi_umi_link1" rgba="1 1 1 1" pos="0.1066203 0.0429998 0.0136096" />
                      <geom name="link6_visual_5" class="visual" type="mesh" mesh="urdf_models_meshes_L5_umi_umi_link3" rgba="0.498039 0.498039 0.498039 1" pos="0.1498023 0.0887898 0.0136095" />
                      <geom name="link6_visual_6" class="visual" type="mesh" mesh="urdf_models_meshes_L5_umi_umi_link2" rgba="0.792157 0.819608 0.933333 1" pos="0.1066203 -0.0430002 0.0136096" />
                      <geom name="link6_visual_7" class="visual" type="mesh" mesh="urdf_models_meshes_L5_umi_umi_link4" rgba="0.498039 0.498039 0.498039 1" pos="0.1498023 -0.0887902 0.0136095" />
                      <geom name="link6_visual_8" class="visual" type="mesh" mesh="urdf_models_meshes_L5_umi_umi_link5" rgba="0.796078 0.823529 0.937255 1" pos="0.12187 0.0195168 0.0136097" />
                      <geom name="link6_visual_9" class="visual" type="mesh" mesh="urdf_models_meshes_L5_umi_umi_link6" rgba="0.796078 0.823529 0.937255 1" pos="0.12187 -0.0195172 0.0136097" />
                      <geom name="link6_collision_1" class="collision" type="mesh" mesh="urdf_models_meshes_DAS_Controller_v3_r5_end_adapter_flange" pos="0 -0.0225 -0.0225" quat="0.500000013397 0.5 0.499999986603 0.5" />
                      <geom name="link6_collision_2" class="collision" type="mesh" mesh="urdf_models_meshes_L5_umi_umi_link_Flange" pos="0.0091 0 0" />
                      <geom name="link6_collision_3" class="collision" type="mesh" mesh="urdf_models_meshes_L5_umi_umi_base_link" pos="0.0999414 3.88e-05 0.0767217" quat="0.99144482142 0 0.130526495702 0" />
                      <geom name="link6_collision_4" class="collision" type="mesh" mesh="urdf_models_meshes_L5_umi_umi_link1" pos="0.1066203 0.0429998 0.0136096" />
                      <geom name="link6_collision_5" class="collision" type="mesh" mesh="urdf_models_meshes_L5_umi_umi_link3" pos="0.1498023 0.0887898 0.0136095" />
                      <geom name="link6_collision_6" class="collision" type="mesh" mesh="urdf_models_meshes_L5_umi_umi_link2" pos="0.1066203 -0.0430002 0.0136096" />
                      <geom name="link6_collision_7" class="collision" type="mesh" mesh="urdf_models_meshes_L5_umi_umi_link4" pos="0.1498023 -0.0887902 0.0136095" />
                      <geom name="link6_collision_8" class="collision" type="mesh" mesh="urdf_models_meshes_L5_umi_umi_link5" pos="0.12187 0.0195168 0.0136097" />
                      <geom name="link6_collision_9" class="collision" type="mesh" mesh="urdf_models_meshes_L5_umi_umi_link6" pos="0.12187 -0.0195172 0.0136097" />
                      <site name="eef_link" size="0.012" rgba="1 0.8 0.05 0.9" group="0" pos="0.0999414 3.88e-05 0.0767217" quat="0.99144482142 0 0.130526495702 0" />
                    </body>
                  </body>
                </body>
              </body>
            </body>
          </body>
        </body>
      </body>
    </body>
  </worldbody>
  <actuator>
    <motor name="J1_motor" joint="J1" gear="1" ctrllimited="true" ctrlrange="-100 100" />
    <motor name="J2_motor" joint="J2" gear="1" ctrllimited="true" ctrlrange="-100 100" />
    <motor name="J3_motor" joint="J3" gear="1" ctrllimited="true" ctrlrange="-100 100" />
    <motor name="J4_motor" joint="J4" gear="1" ctrllimited="true" ctrlrange="-100 100" />
    <motor name="J5_motor" joint="J5" gear="1" ctrllimited="true" ctrlrange="-100 100" />
    <motor name="J6_motor" joint="J6" gear="1" ctrllimited="true" ctrlrange="-100 100" />
    <motor name="abad_L_Joint_motor" joint="abad_L_Joint" gear="1" ctrllimited="true" ctrlrange="-80 80" />
    <motor name="hip_L_Joint_motor" joint="hip_L_Joint" gear="1" ctrllimited="true" ctrlrange="-80 80" />
    <motor name="knee_L_Joint_motor" joint="knee_L_Joint" gear="1" ctrllimited="true" ctrlrange="-80 80" />
    <motor name="ankle_L_Joint_motor" joint="ankle_L_Joint" gear="1" ctrllimited="true" ctrlrange="-20 20" />
    <motor name="abad_R_Joint_motor" joint="abad_R_Joint" gear="1" ctrllimited="true" ctrlrange="-80 80" />
    <motor name="hip_R_Joint_motor" joint="hip_R_Joint" gear="1" ctrllimited="true" ctrlrange="-80 80" />
    <motor name="knee_R_Joint_motor" joint="knee_R_Joint" gear="1" ctrllimited="true" ctrlrange="-80 80" />
    <motor name="ankle_R_Joint_motor" joint="ankle_R_Joint" gear="1" ctrllimited="true" ctrlrange="-20 20" />
  </actuator>
  <sensor>
    <framequat name="imu_quat" objtype="site" objname="imu" />
    <gyro name="imu_gyro" site="imu" />
    <accelerometer name="imu_acc" site="imu" />
    <jointpos name="J1_pos" joint="J1" />
    <jointvel name="J1_vel" joint="J1" />
    <jointpos name="J2_pos" joint="J2" />
    <jointvel name="J2_vel" joint="J2" />
    <jointpos name="J3_pos" joint="J3" />
    <jointvel name="J3_vel" joint="J3" />
    <jointpos name="J4_pos" joint="J4" />
    <jointvel name="J4_vel" joint="J4" />
    <jointpos name="J5_pos" joint="J5" />
    <jointvel name="J5_vel" joint="J5" />
    <jointpos name="J6_pos" joint="J6" />
    <jointvel name="J6_vel" joint="J6" />
    <jointpos name="abad_L_Joint_pos" joint="abad_L_Joint" />
    <jointvel name="abad_L_Joint_vel" joint="abad_L_Joint" />
    <jointpos name="hip_L_Joint_pos" joint="hip_L_Joint" />
    <jointvel name="hip_L_Joint_vel" joint="hip_L_Joint" />
    <jointpos name="knee_L_Joint_pos" joint="knee_L_Joint" />
    <jointvel name="knee_L_Joint_vel" joint="knee_L_Joint" />
    <jointpos name="ankle_L_Joint_pos" joint="ankle_L_Joint" />
    <jointvel name="ankle_L_Joint_vel" joint="ankle_L_Joint" />
    <jointpos name="abad_R_Joint_pos" joint="abad_R_Joint" />
    <jointvel name="abad_R_Joint_vel" joint="abad_R_Joint" />
    <jointpos name="hip_R_Joint_pos" joint="hip_R_Joint" />
    <jointvel name="hip_R_Joint_vel" joint="hip_R_Joint" />
    <jointpos name="knee_R_Joint_pos" joint="knee_R_Joint" />
    <jointvel name="knee_R_Joint_vel" joint="knee_R_Joint" />
    <jointpos name="ankle_R_Joint_pos" joint="ankle_R_Joint" />
    <jointvel name="ankle_R_Joint_vel" joint="ankle_R_Joint" />
  </sensor>
</mujoco>